Workbook

Sheet ORGANOGRAMA

Sheet Funções - Faz Energy
A3: GENTE E GESTÃO
A4: FINANCEIRO
A5: MARKETING
A6: T.I.
A7: COMERCIAL

Sheet Fluxograma

Sheet Simulação-MMN
A2: TAXA DE ADESÃO | D2: A Prazo | E2: A vista | G2: UPGRADE CLIENTE | J2: A Prazo | K2: A vista | M2: Mensalidade Revo | P2: Meses | R2: Fazenda do Sol | U2: Rem | W2: Venda de modulos | Z2: Rem
D3: 1799 | E3: 1599 | J3: 1299.99 | K3: 1099 | M3: Remuneração recorrente | O3: 500 | P3: 24 | R3: Valor da conta | T3: 400 | U3: 0.12 | W3: Valor da usina | Y3: 15000
S4: Desconto total | T4: 0.33 | X4: Desconto total | AB4: Simulação de faturamento
A5: Calculo de rentabilidade | G5: Calculo de rentabilidade | M5: Calculo de rentabilidade | R5: Calculo de rentabilidade | W5: Calculo de rentabilidade | AC5: N | AD5: TOTAL
A6: Item | B6: Descrição | C6: Valor / Taxa | D6: Total | E6: Total | G6: Item | H6: Descrição | I6: Valor / Taxa | J6: Total | K6: Total | M6: Item | N6: Descrição | O6: Valor / Taxa | P6: Total | R6: Item | S6: Descrição | T6: Valor / Taxa | U6: Total | W6: Item | X6: Descrição | Y6: Valor / Taxa | Z6: Total | AB6: LICENCA ANUAL | AC6: 5000 | AD6: =AC6*D18 -> 3776400
A7: 1 | B7: Impostos / NF | C7: 0.15 | D7: =C7*D3 -> 269.85 | E7: =E3*C7 -> 239.85 | G7: 1 | H7: Impostos / NF | I7: 0.15 | J7: =I7*J3 -> 194.9985 | K7: =K3*I7 -> 164.85 | M7: 1 | N7: Impostos / NF | O7: 0.15 | P7: =O7*O3 -> 75 | R7: 1 | S7: Impostos / NF | T7: 0.15 | U7: =T7*U3*T3 -> 7.2 | W7: 1 | X7: Impostos / NF | Y7: 0.025 | Z7: =Y7*Y3 -> 375 | AB7: UPGRADES CLIENTES | AC7: 5000 | AD7: =J18*AC7 -> 1979964
A8: 2 | B8: Taxa de transação | C8: 0.13 | D8: =C8*D3 -> 233.87 | E8: 0 | G8: 2 | H8: Taxa de transação | I8: 0.13 | J8: =I8*J3 -> 168.9987 | K8: 0 | M8: 2 | N8: Vendedor | O8: 0.025 | P8: =$O$3*O8 -> 12.5 | R8: 2 | S8: Vendedor | T8: 0.05 | U8: =$T$3*T8 -> 20 | W8: 2 | X8: Vendedor | Y8: 0.05 | Z8: =$Y$3*Y8 -> 750 | AB8: Instalações | AC8: 12000
A9: 3 | B9: Indicação direta | C9: 300 | D9: =C9 -> 300 | E9: =D9 -> 300 | G9: 3 | H9: Indicação direta | I9: 300 | J9: 300 | K9: 300 | M9: 3 | N9: Rede Nível 1 | O9: 0.005 | P9: =$O$3*O9 -> 2.5 | R9: 3 | S9: Rede Nível 1 | T9: 0.01 | U9: =$T$3*T9 -> 4 | W9: 3 | X9: Rede Nível 1 | Y9: 0.005 | Z9: =$Y$3*Y9 -> 75 | AB9: Volume de contas Recorrente | AC9: =O3 -> 500 | AD9: =AC8*P18 -> 360000
A10: 4 | B10: Rede Nível 2 | C10: 50 | D10: =C10 -> 50 | E10: =D10 -> 50 | G10: 4 | H10: Rede Nível 2 | I10: 50 | J10: =I10 -> 50 | K10: =J10 -> 50 | M10: 4 | N10: Rede Nível 2 | O10: 0.003 | P10: =$O$3*O10 -> 1.5 | R10: 4 | S10: Rede Nível 2 | T10: 0.005 | U10: =$T$3*T10 -> 2 | W10: 4 | X10: Rede Nível 2 | Y10: 0.004 | Z10: =$Y$3*Y10 -> 60 | AB10: Volume de Contas D+0 | AC10: =O3 -> 500 | AD10: =AC8*P19 -> 1500000
A11: 5 | B11: Rede Nível 3 | C11: 40 | D11: =C11 -> 40 | E11: =D11 -> 40 | G11: 5 | H11: Rede Nível 3 | I11: 40 | J11: =I11 -> 40 | K11: =J11 -> 40 | M11: 5 | N11: Rede Nível 3 | O11: 0.003 | P11: =$O$3*O11 -> 1.5 | R11: 5 | S11: Rede Nível 3 | T11: 0.005 | U11: =$T$3*T11 -> 2 | W11: 5 | X11: Rede Nível 3 | Y11: 0.004 | Z11: =$Y$3*Y11 -> 60
A12: 6 | B12: Rede Nível 4 | C12: 30 | D12: =C12 -> 30 | E12: =D12 -> 30 | G12: 6 | H12: Rede Nível 4 | I12: 30 | J12: =I12 -> 30 | K12: =J12 -> 30 | M12: 6 | N12: Rede Nível 4 | O12: 0.002 | P12: =$O$3*O12 -> 1 | R12: 6 | S12: Rede Nível 4 | T12: 0.005 | U12: =$T$3*T12 -> 2 | W12: 6 | X12: Rede Nível 4 | Y12: 0.004 | Z12: =$Y$3*Y12 -> 60 | AC12: TOTAL | AD12: =SUM(AD6:AD10) -> 7616364
A13: 7 | B13: Rede Nível 5 | C13: 20 | D13: =C13 -> 20 | E13: =D13 -> 20 | G13: 7 | H13: Rede Nível 5 | I13: 20 | J13: =I13 -> 20 | K13: =J13 -> 20 | M13: 7 | N13: Rede Nível 5 | O13: 0.002 | P13: =$O$3*O13 -> 1 | R13: 7 | S13: Rede Nível 5 | T13: 0.005 | U13: =$T$3*T13 -> 2 | W13: 7 | X13: Rede Nível 5 | Y13: 0.003 | Z13: =$Y$3*Y13 -> 45
A14: 8 | B14: Plano de Carreira | C14: 100 | D14: =C14 -> 100 | E14: =D14 -> 100 | G14: 9 | H14: Plano de Carreira | I14: 100 | J14: =I14 -> 100 | K14: =J14 -> 100 | M14: 8 | N14: Remuneração K | O14: 0 | P14: =O3*O14 -> 0 | R14: 8 | S14: Remuneração K | T14: 0 | U14: =T3*T14 -> 0 | W14: 8 | X14: Custos usina | Y14: 0.64 | Z14: =Y3*Y14 -> 9600
M15: 9 | N15: Comissão Upfront | O15: 0.6 | P15: =O15*O3 -> 300 | R15: 9 | S15: Comissão Upfront | T15: 0.9 | U15: =T15*T3 -> 360 | W15: 9 | X15: Custos com inst | Y15: 0.11 | Z15: =Y15*Y3 -> 1650 | AB15: *saldo em 24 meses
M16: 10 | N16: Plano de Carreira | O16: 0.1 | P16: =O3*O16 -> 50 | R16: 10 | S16: Plano de Carreira | T16: 0.1 | U16: =T3*T16 -> 40 | W16: 10 | X16: poxxxx venda | Y16: 0.04 | Z16: =Y16*Y3 -> 600
W17: 11 | X17: Plano de Carreira | Y17: 0.02 | Z17: =Y3*Y17 -> 300
A18: SALDO FAZ ENERGY | D18: =D3-SUM(D7:D16) -> 755.28 | E18: =E3-SUM(E7:E14) -> 819.15 | G18: SALDO FAZ ENERGY | J18: =J3-SUM(J7:J14) -> 395.9928 | K18: =K3-SUM(K7:K14) -> 394.15 | M18: SALDO (24 meses) | P18: ='Simulador-Rent Revo'!AA7 -> 30 | R18: SALDO (24 meses) | U18: ='Simulador-Rent Revo'!AF7 -> 0 | Z18: ='Simulador-Rent Revo'!AK7 -> 0
M19: SALDO D+0 | P19: =O3-SUM(P7)-P15 -> 125 | R19: SALDO D+0 | U19: =(U15*0.85)-U16 -> 266
W20: SALDO FAZ ENERGY | Z20: =Y3-SUM(Z7:Z18)+Z16 -> 2025 | AA20: =Z20/Y3 -> 0.135
M21: SALDO TOTAL FAZ ENERGY | P21: =O3-SUM(P15:P16)-P7+P18 -> 105 | Q21: =P21/O3 -> 0.21 | R21: SALDO FAZ ENERGY - Recorrente | U21: =(T3*U3)-SUM(U7:U13) -> 8.8 | W21: SALDO FAZ ENERGY - disponivel | Z21: =Y3-SUM(Z7:Z17) -> 1425 | AA21: =Z21/Y3 -> 0.095
B29: Numero de Instalações vendidades para Break-Even do Investimento Licença | D29: Instalações | H29: Numero de Instalações vendidades para Break-Even do Investimento Licença | J29: Instalações
D30: 9 | J30: 7
D31: =P15/D3 -> 0.16675931 | J31: =P15/J3 -> 0.23077101
D32: =D30*D31 -> 1.5008338 | J32: =J30*J31 -> 1.615397
B34: Break-Even do Investimento Licença - Esforço mínimo | D34: Instalações | E34: Licenças | H34: Break-Even do Investimento Licença - Esforço mínimo | J34: REVO | K34: Licenças | L34: VD | M34: Ass
D35: 4 | E35: 2 | J35: 0 | K35: 2 | L35: 0 | M35: 3
D36: =P15/D3 -> 0.16675931 | E36: =C9/D3 -> 0.16675931 | J36: =$P$15/$J$3 -> 0.23077101 | K36: =$I$9/$J$3 -> 0.23077101 | L36: =$Z$8/$J$3 -> 0.57692751 | M36: =$U$8/$J$3 -> 0.015384734
D37: =D35*D36 -> 0.66703724 | E37: =E35*E36 -> 0.33351862 | J37: =J35*J36 -> 0 | K37: =K35*K36 -> 0.46154201 | L37: =L36*L35 -> 0 | M37: =M36*M35 -> 0.046154201
D38: =D35*P15 -> 1200 | E38: =E35*C9 -> 600 | J38: =J35*$P$15 -> 0 | K38: =K35*$I$9 -> 600 | L38: =L35*$Z$8 -> 0 | M38: =$U$8*M35 -> 60 | N38: R$ | O38: =SUM(J38:M38) -> 660
J39: =0.1*$O$3*J35 -> 0 | K39: =100*K35 -> 200 | L39: =L35*$Y$3*$Y$17 -> 0 | M39: =0.1*M35*$T$3 -> 120 | N39: PTS | O39: =SUM(J39:M39) -> 320 | P39: =O39+O47+O54 -> 2260
H42: Break-Even do Investimento Licença - Esforço mínimo | J42: REVO | K42: Licenças | L42: VD | M42: Ass
J43: 1 | K43: 2 | L43: 2 | M43: 3
J44: =$P$15/$J$3 -> 0.23077101 | K44: =$I$9/$J$3 -> 0.23077101 | L44: =$Z$8/$J$3 -> 0.57692751 | M44: =$U$8/$J$3 -> 0.015384734
J45: =J43*J44 -> 0.23077101 | K45: =K43*K44 -> 0.46154201 | L45: =L44*L43 -> 1.153855 | M45: =M44*M43 -> 0.046154201
J46: =J43*$P$15 -> 300 | K46: =K43*$I$9 -> 600 | L46: =L43*$Z$8 -> 1500 | M46: =$U$8*M43 -> 60 | N46: R$ | O46: =SUM(J46:M46) -> 2460
J47: =0.1*$O$3*J43 -> 50 | K47: =100*K43 -> 200 | L47: =L43*$Y$3*$Y$17 -> 600 | M47: =0.1*M43*$T$3 -> 120 | N47: PTS | O47: =SUM(J47:M47) -> 970
H49: Break-Even do Investimento Licença - Esforço mínimo | J49: REVO | K49: Licenças | L49: VD | M49: Ass
J50: 1 | K50: 2 | L50: 2 | M50: 3
J51: =$P$15/$J$3 -> 0.23077101 | K51: =$I$9/$J$3 -> 0.23077101 | L51: =$Z$8/$J$3 -> 0.57692751 | M51: =$U$8/$J$3 -> 0.015384734
J52: =J50*J51 -> 0.23077101 | K52: =K50*K51 -> 0.46154201 | L52: =L51*L50 -> 1.153855 | M52: =M51*M50 -> 0.046154201
...

Sheet Base de Calculo-MMN
M1: Conta mensal | N1: Meses
B2: TAXA DE ADESÃO | C2: 1400 | G2: TAXA DE Instalação | H2: 1200 | K2: Remuneração recorrente | M2: ='Simulação-MMN'!O3 -> 500 | N2: 48
A4: Calculo de rentabilidade | F4: Calculo de rentabilidade | K4: Calculo de rentabilidade
A5: Item | B5: Descrição | C5: Valor / Taxa | D5: Total | F5: Item | G5: Descrição | H5: Valor / Taxa | I5: Total | K5: Item | L5: Descrição | M5: Valor / Taxa | N5: Total
A6: 1 | B6: Impostos / NF | C6: 0.15 | D6: =C6*C2 -> 210 | F6: 1 | G6: Impostos / NF | H6: 0.15 | I6: =H6*H2 -> 180 | K6: 1 | L6: Impostos / NF | M6: 0.15 | N6: =M6*M2*2 -> 150
A7: 2 | B7: Taxa de transação | C7: 0.11 | D7: =C7*C2 -> 154 | F7: 2 | G7: Taxa de transação | H7: 0.11 | I7: =H7*H2 -> 132 | K7: 2 | L7: Vendedor | M7: 0.02 | N7: =$M$2*M7 -> 10
A8: 3 | B8: Indicação direta | C8: 300 | D8: 300 | F8: 3 | G8: Indicação direta | H8: 300 | I8: 300 | K8: 3 | L8: Rede Nível 1 | M8: 0.003 | N8: =$M$2*M8 -> 1.5
A9: 4 | B9: Rede Nível 2 | C9: 120 | D9: =C9 -> 120 | F9: 4 | G9: Rede Nível 1 | H9: 50 | I9: =H9 -> 50 | K9: 4 | L9: Rede Nível 2 | M9: 0.003 | N9: =$M$2*M9 -> 1.5
A10: 5 | B10: Rede Nível 3 | C10: 60 | D10: =C10 -> 60 | F10: 5 | G10: Rede Nível 2 | H10: 40 | I10: =H10 -> 40 | K10: 5 | L10: Rede Nível 3 | M10: 0.003 | N10: =$M$2*M10 -> 1.5
A11: 6 | B11: Rede Nível 4 | C11: 36 | D11: =C11 -> 36 | F11: 6 | G11: Rede Nível 3 | H11: 30 | I11: =H11 -> 30 | K11: 6 | L11: Rede Nível 4 | M11: 0.003 | N11: =$M$2*M11 -> 1.5
A12: 7 | B12: Rede Nível 5 | C12: 24 | D12: =C12 -> 24 | F12: 7 | G12: Rede Nível 4 | H12: 20 | I12: =H12 -> 20 | K12: 7 | L12: Rede Nível 5 | M12: 0.003 | N12: =$M$2*M12 -> 1.5
A13: 8 | B13: Reserva - Premiação | C13: 50 | D13: 50 | F13: 8 | G13: Rede Nível 5 | H13: 10 | I13: =H13 -> 10 | K13: 8 | L13: Remuneração K | M13: ='Simulação-MMN'!O14 -> 0 | N13: =M2*M13 -> 0
F14: 9 | G14: Reserva - Premiação | H14: 50 | I14: 50
B16: SALDO | D16: =C2-SUM(D6:D14) -> 446 | G16: SALDO | I16: =H2-SUM(I6:I14) -> 388 | L16: SALDO (48 meses) | N16: ='Simulador-Rent Revo'!AY3 -> 0

Sheet Plano de Carreira
A1: Plano de Carreira Faz Energy | D1: Mensalidade
A2: Adesão | B2: 100 | D2: 300
A3: Upgrade | B3: 100
A4: Revo | B4: =D2*0.1 -> 30 | C4: 10% da mensalidade
A5: Energia por assinatura | C5: 10% da mensalidade
A6: Venda de Sistema | C6: 2% da venda total

Sheet Simulador-Rent Revo
C2: M0 | D2: M1 | E2: M2 | F2: M3 | G2: M4 | H2: M5 | I2: M6 | J2: M7 | K2: M8 | L2: M9 | M2: M10 | N2: M11 | O2: M12 | P2: M13 | Q2: M14 | R2: M15 | S2: M16 | T2: M17 | U2: M18 | V2: M19 | W2: M20 | X2: M21 | Y2: M22 | Z2: M23 | AA2: M24
A3: ="Conta Energia de R$ "&'Base de Calculo-MMN'!M2&"" -> Conta Energia de R$ 500 | C3: ='Base de Calculo-MMN'!M2 -> 500 | D3: =$C$3*0.05 -> 25 | E3: =$C$3*0.05 -> 25 | F3: =$C$3*0.05 -> 25 | G3: =$C$3*0.05 -> 25 | H3: =$C$3*0.05 -> 25 | I3: =$C$3*0.05 -> 25 | J3: =$C$3*0.05 -> 25 | K3: =$C$3*0.05 -> 25 | ... AA3: =$C$3*0.05 -> 25
A4: Imposto | B4: 0.15 | C4: =C3*B4 -> 75 | D4: =D3*$B$4 -> 3.75 | E4: =E3*$B$4 -> 3.75 | F4: =F3*$B$4 -> 3.75 | G4: =G3*$B$4 -> 3.75 | H4: =H3*$B$4 -> 3.75 | I4: =I3*$B$4 -> 3.75 | J4: =J3*$B$4 -> 3.75 | K4: =K3*$B$4 -> 3.75 | ... AA4: =AA3*$B$4 -> 3.75
A5: ="Comissão da rede "&SUM('Simulação-MMN'!O8:O13) -> Comissão da rede 0,04 | B5: =SUM('Simulação-MMN'!O8:O13) -> 0.04 | D5: =$C$3*$B$5 -> 20 | E5: =$C$3*$B$5 -> 20 | F5: =$C$3*$B$5 -> 20 | G5: =$C$3*$B$5 -> 20 | H5: =$C$3*$B$5 -> 20 | I5: =$C$3*$B$5 -> 20 | J5: =$C$3*$B$5 -> 20 | K5: =$C$3*$B$5 -> 20 | ... AA5: =$C$3*$B$5 -> 20
A6: Saldo | D6: =D3-D4-D5 -> 1.25 | E6: =E3-E4-E5 -> 1.25 | F6: =F3-F4-F5 -> 1.25 | G6: =G3-G4-G5 -> 1.25 | H6: =H3-H4-H5 -> 1.25 | I6: =I3-I4-I5 -> 1.25 | J6: =J3-J4-J5 -> 1.25 | K6: =K3-K4-K5 -> 1.25 | ... AA6: =AA3-AA4-AA5 -> 1.25
A7: ="Rentabilidade "&'Simulação-MMN'!O14 -> Rentabilidade 0 | B7: ='Simulação-MMN'!O14 -> 0 | E7: =D6*(1+$B$7)+E6 -> 2.5 | F7: =E7*(1+$B$7)+F6 -> 3.75 | G7: =F7*(1+$B$7)+G6 -> 5 | H7: =G7*(1+$B$7)+H6 -> 6.25 | I7: =H7*(1+$B$7)+I6 -> 7.5 | J7: =I7*(1+$B$7)+J6 -> 8.75 | K7: =J7*(1+$B$7)+K6 -> 10 | L7: =K7*(1+$B$7)+L6 -> 11.25 | M7: =L7*(1+$B$7)+M6 -> 12.5 | ... AA7: =Z7*(1+$B$7)+AA6 -> 30
A14: Última atualização: 19/dez/2024 | C14: https://www12.senado.leg.br/ifi/dados/arquivos/projecoes-ifi
C15: Projeções (cenário base)
B16: 2023 | C16: 2024 | D16: 2025 | E16: 2026 | F16: 2027 | G16: 2028 | H16: 2029 | I16: 2030 | J16: 2031 | K16: 2032 | L16: 2033 | M16: 2034
A17: PIB – crescimento real (% a.a.) | B17: 3.24 | C17: 3.53 | D17: 1.86 | E17: 2.13 | F17: 2.16 | G17: 2.18 | H17: 2.22 | I17: 2.27 | J17: 2.27 | K17: 2.29 | L17: 2.34 | M17: 2.31
A18: PIB – nominal (R$ bilhões) | B18: 10943 | C18: 11809 | D18: 12600 | E18: 13408 | F18: 14224 | G18: 15048 | H18: 15936 | I18: 16884 | J18: 17889 | K18: 18958 | L18: 20100 | M18: 21305
A19: IPCA – acum. (% no ano) | B19: 4.62 | C19: 4.93 | D19: 4.44 | E19: 3.64 | F19: 3.3 | G19: 3 | H19: 3 | I19: 3 | J19: 3 | K19: 3 | L19: 3 | M19: 3
A20: Taxa de câmbio - fim de período (R$/US$) | B20: 4.84 | C20: 5.95 | D20: 5.95 | E20: 6.05 | F20: 6.12 | G20: 6.18 | H20: 6.24 | I20: 6.3 | J20: 6.37 | K20: 6.43 | L20: 6.49 | M20: 6.56
A21: Ocupação - crescimento (%) | B21: 1.37 | C21: 2.7 | D21: 1.02 | E21: 1.17 | F21: 1.19 | G21: 1.2 | H21: 1.22 | I21: 1.25 | J21: 1.25 | K21: 1.26 | L21: 1.29 | M21: 1.27
A22: Massa salarial - crescimento (%) | B22: 6.91 | C22: 6.81 | D22: 2.24 | E22: 2.13 | F22: 2.16 | G22: 2.18 | H22: 2.22 | I22: 2.27 | J22: 2.27 | K22: 2.29 | L22: 2.34 | M22: 2.31
A23: Selic – fim de período (% a.a.) | B23: 11.75 | C23: 12.25 | D23: 14.25 | E23: 11.75 | F23: 10.5 | G23: 9.5 | H23: 8.5 | I23: 8 | J23: 8 | K23: 8 | L23: 8 | M23: 8
A24: Juros reais ex-ante (% a.a.) | B24: 5.94 | C24: 7.5 | D24: 7.18 | E24: 6.38 | F24: 5.78 | G24: 5.21 | H24: 4.78 | I24: 4.81 | J24: 4.83 | K24: 4.84 | L24: 4.84 | M24: 4.84
A25: Resultado Primário do Setor Público Consolidado (% do PIB) | B25: -2.29 | C25: -0.36 | D25: -0.71 | E25: -1.05 | F25: -1.04 | G25: -1.17 | H25: -1.32 | I25: -1.45 | J25: -1.59 | K25: -1.68 | L25: -1.28 | M25: -1.21
A26: dos quais Governo Central | B26: -2.44 | C26: -0.42 | D26: -0.71 | E26: -1 | F26: -1.03 | G26: -1.14 | H26: -1.29 | I26: -1.41 | J26: -1.55 | K26: -1.65 | L26: -1.24 | M26: -1.17
A27: Juros Nominais Líquidos (% do PIB) | B27: 6.62 | C27: 7.68 | D27: 8.91 | E27: 8.63 | F27: 8.39 | G27: 8.12 | H27: 7.51 | I27: 7.23 | J27: 7.11 | K27: 7.11 | L27: 7.07 | M27: 7.07
A28: Resultado Nominal (% do PIB) | B28: -8.91 | C28: -8.03 | D28: -9.62 | E28: -9.68 | F28: -9.43 | G28: -9.29 | H28: -8.84 | I28: -8.68 | J28: -8.7 | K28: -8.79 | L28: -8.35 | M28: -8.28
A29: Dívida Bruta do Governo Geral (% do PIB) | B29: 73.8 | C29: 78.3 | D29: 81.4 | E29: 86.3 | F29: 91 | G29: 95.3 | H29: 99 | I29: 102.3 | J29: 105.9 | K29: 109.6 | L29: 112.9 | M29: 116.3
